{"status": "FAILURE", "result": {"exc_type": "PrepareDataRuntimeError", "exc_message": ["Data provisioning failed for all requests!\nDID=testing:prepare_data_test.txt: Failed to stage file for alexclarke via Cavern API: Failed to submit staging job"], "exc_module": "prepare_data.util.exceptions"}, "traceback": "Traceback (most recent call last):\n  File \"/usr/local/lib/python3.12/site-packages/celery/app/trace.py\", line 453, in trace_task\n    R = retval = fun(*args, **kwargs)\n                 ^^^^^^^^^^^^^^^^^^^^\n  File \"/usr/local/lib/python3.12/site-packages/celery/app/trace.py\", line 736, in __protected_call__\n    return self.run(*args, **kwargs)\n           ^^^^^^^^^^^^^^^^^^^^^^^^^\n  File \"/usr/local/lib/python3.12/site-packages/prepare_data/tasks/prepare_data.py\", line 19, in prepare_data_task\n    approach.validate_input_and_prepare_data(\n  File \"/usr/local/lib/python3.12/site-packages/prepare_data/approaches/approach.py\", line 104, in validate_input_and_prepare_data\n    raise PrepareDataRuntimeError(err_msg)\nprepare_data.util.exceptions.PrepareDataRuntimeError: Data provisioning failed for all requests!\nDID=testing:prepare_data_test.txt: Failed to stage file for alexclarke via Cavern API: Failed to submit staging job\n", "children": [], "date_done": "2025-08-12T15:45:21.247670+00:00", "task_id": "d8b830a1-36aa-4e4b-b992-1bdc62a5f34b"}