{"status": "FAILURE", "result": {"exc_type": "TypeError", "exc_message": ["Approach.validate_input_and_prepare_data() takes 5 positional arguments but 6 were given"], "exc_module": "builtins"}, "traceback": "Traceback (most recent call last):\n  File \"/usr/local/lib/python3.12/site-packages/celery/app/trace.py\", line 453, in trace_task\n    R = retval = fun(*args, **kwargs)\n                 ^^^^^^^^^^^^^^^^^^^^\n  File \"/usr/local/lib/python3.12/site-packages/celery/app/trace.py\", line 736, in __protected_call__\n    return self.run(*args, **kwargs)\n           ^^^^^^^^^^^^^^^^^^^^^^^^^\n  File \"/usr/local/lib/python3.12/site-packages/prepare_data/tasks/prepare_data.py\", line 19, in prepare_data_task\n    approach.validate_input_and_prepare_data(\nTypeError: Approach.validate_input_and_prepare_data() takes 5 positional arguments but 6 were given\n", "children": [], "date_done": "2025-08-12T13:49:01.826861+00:00", "task_id": "23aa455d-461e-4b56-acae-e9cc0697a4df"}